kill @e[distance=..5,type=!player,type=!wolf,type=!item]

setblock ~ ~-1 ~ oak_planks destroy

fill ~2 ~-1 ~2 ~-2 ~-1 ~-2 oak_planks destroy

setblock ~3 ~-1 ~ oak_planks destroy
setblock ~3 ~ ~ oak_door[facing=west,hinge=left,half=lower] destroy
setblock ~3 ~1 ~ oak_door[facing=west,hinge=left,half=upper] destroy

setblock ~3 ~-1 ~1 cobblestone destroy
setblock ~3 ~-1 ~2 cobblestone destroy
setblock ~3 ~-1 ~3 cobblestone destroy
setblock ~2 ~-1 ~3 cobblestone destroy
setblock ~1 ~-1 ~3 cobblestone destroy
setblock ~ ~-1 ~3 cobblestone destroy
setblock ~-1 ~-1 ~3 cobblestone destroy
setblock ~-2 ~-1 ~3 cobblestone destroy
setblock ~-3 ~-1 ~3 cobblestone destroy
setblock ~-3 ~-1 ~2 cobblestone destroy
setblock ~-3 ~-1 ~1 cobblestone destroy
setblock ~-3 ~-1 ~ cobblestone destroy
setblock ~-3 ~-1 ~-1 cobblestone destroy
setblock ~-3 ~-1 ~-2 cobblestone destroy
setblock ~-3 ~-1 ~-3 cobblestone destroy
setblock ~-2 ~-1 ~-3 cobblestone destroy
setblock ~-1 ~-1 ~-3 cobblestone destroy
setblock ~ ~-1 ~-3 cobblestone destroy
setblock ~1 ~-1 ~-3 cobblestone destroy
setblock ~2 ~-1 ~-3 cobblestone destroy
setblock ~3 ~-1 ~-3 cobblestone destroy
setblock ~3 ~-1 ~-2 cobblestone destroy
setblock ~3 ~-1 ~-1 cobblestone destroy

setblock ~3 ~ ~1 cobblestone destroy
setblock ~3 ~ ~2 cobblestone destroy
setblock ~3 ~ ~3 oak_log destroy
setblock ~2 ~ ~3 cobblestone destroy
setblock ~1 ~ ~3 cobblestone destroy
setblock ~ ~ ~3 cobblestone destroy
setblock ~-1 ~ ~3 cobblestone destroy
setblock ~-2 ~ ~3 cobblestone destroy
setblock ~-3 ~ ~3 oak_log destroy
setblock ~-3 ~ ~2 cobblestone destroy
setblock ~-3 ~ ~1 cobblestone destroy
setblock ~-3 ~ ~ cobblestone destroy
setblock ~-3 ~ ~-1 cobblestone destroy
setblock ~-3 ~ ~-2 cobblestone destroy
setblock ~-3 ~ ~-3 oak_log destroy
setblock ~-2 ~ ~-3 cobblestone destroy
setblock ~-1 ~ ~-3 cobblestone destroy
setblock ~ ~ ~-3 cobblestone destroy
setblock ~1 ~ ~-3 cobblestone destroy
setblock ~2 ~ ~-3 cobblestone destroy
setblock ~3 ~ ~-3 oak_log destroy
setblock ~3 ~ ~-2 cobblestone destroy
setblock ~3 ~ ~-1 cobblestone destroy

setblock ~3 ~1 ~1 oak_planks destroy
setblock ~3 ~1 ~2 oak_planks destroy
setblock ~3 ~1 ~3 oak_log destroy
setblock ~2 ~1 ~3 oak_planks destroy
setblock ~1 ~1 ~3 oak_planks destroy
setblock ~ ~1 ~3 glass_pane destroy
setblock ~-1 ~1 ~3 oak_planks destroy
setblock ~-2 ~1 ~3 oak_planks destroy
setblock ~-3 ~1 ~3 oak_log destroy
setblock ~-3 ~1 ~2 oak_planks destroy
setblock ~-3 ~1 ~1 oak_planks destroy
setblock ~-3 ~1 ~ glass_pane destroy
setblock ~-3 ~1 ~-1 oak_planks destroy
setblock ~-3 ~1 ~-2 oak_planks destroy
setblock ~-3 ~1 ~-3 oak_log destroy
setblock ~-2 ~1 ~-3 oak_planks destroy
setblock ~-1 ~1 ~-3 oak_planks destroy
setblock ~ ~1 ~-3 glass_pane destroy
setblock ~1 ~1 ~-3 oak_planks destroy
setblock ~2 ~1 ~-3 oak_planks destroy
setblock ~3 ~1 ~-3 oak_log destroy
setblock ~3 ~1 ~-2 oak_planks destroy
setblock ~3 ~1 ~-1 oak_planks destroy

setblock ~3 ~2 ~ oak_planks destroy
setblock ~3 ~2 ~1 oak_planks destroy
setblock ~3 ~2 ~2 oak_planks destroy
setblock ~3 ~2 ~3 oak_log destroy
setblock ~2 ~2 ~3 oak_planks destroy
setblock ~1 ~2 ~3 oak_planks destroy
setblock ~ ~2 ~3 oak_planks destroy
setblock ~-1 ~2 ~3 oak_planks destroy
setblock ~-2 ~2 ~3 oak_planks destroy
setblock ~-3 ~2 ~3 oak_log destroy
setblock ~-3 ~2 ~2 oak_planks destroy
setblock ~-3 ~2 ~1 oak_planks destroy
setblock ~-3 ~2 ~ oak_planks destroy
setblock ~-3 ~2 ~-1 oak_planks destroy
setblock ~-3 ~2 ~-2 oak_planks destroy
setblock ~-3 ~2 ~-3 oak_log destroy
setblock ~-2 ~2 ~-3 oak_planks destroy
setblock ~-1 ~2 ~-3 oak_planks destroy
setblock ~ ~2 ~-3 oak_planks destroy
setblock ~1 ~2 ~-3 oak_planks destroy
setblock ~2 ~2 ~-3 oak_planks destroy
setblock ~3 ~2 ~-3 oak_log destroy
setblock ~3 ~2 ~-2 oak_planks destroy
setblock ~3 ~2 ~-1 oak_planks destroy

setblock ~3 ~3 ~ oak_planks destroy
setblock ~3 ~3 ~1 oak_planks destroy
setblock ~3 ~3 ~2 oak_planks destroy
setblock ~3 ~3 ~3 oak_log destroy
setblock ~2 ~3 ~3 oak_planks destroy
setblock ~1 ~3 ~3 oak_planks destroy
setblock ~ ~3 ~3 oak_planks destroy
setblock ~-1 ~3 ~3 oak_planks destroy
setblock ~-2 ~3 ~3 oak_planks destroy
setblock ~-3 ~3 ~3 oak_log destroy
setblock ~-3 ~3 ~2 oak_planks destroy
setblock ~-3 ~3 ~1 oak_planks destroy
setblock ~-3 ~3 ~ oak_planks destroy
setblock ~-3 ~3 ~-1 oak_planks destroy
setblock ~-3 ~3 ~-2 oak_planks destroy
setblock ~-3 ~3 ~-3 oak_log destroy
setblock ~-2 ~3 ~-3 oak_planks destroy
setblock ~-1 ~3 ~-3 oak_planks destroy
setblock ~ ~3 ~-3 oak_planks destroy
setblock ~1 ~3 ~-3 oak_planks destroy
setblock ~2 ~3 ~-3 oak_planks destroy
setblock ~3 ~3 ~-3 oak_log destroy
setblock ~3 ~3 ~-2 oak_planks destroy
setblock ~3 ~3 ~-1 oak_planks destroy

fill ~2 ~3 ~2 ~-2 ~3 ~-2 oak_planks destroy

setblock ~ ~2 ~2 wall_torch[facing=north] destroy
setblock ~ ~2 ~-2 wall_torch[facing=south] destroy

setblock ~-1 ~ ~ red_bed[facing=west,part=foot] destroy
setblock ~-2 ~ ~ red_bed[facing=west,part=head] destroy
setblock ~-2 ~ ~-1 chest[facing=east] destroy
setblock ~-2 ~ ~1 crafting_table destroy